Workbook

Sheet 설명서
A1: 🏥 [근무표 자동화 스케줄러 사용 설명서] | K1: 만든사람: | M1: 동남보건대 간호학과 21학번 송민영
M2: 성균관대 기계공학부 20학번 김정진
K3: 간호관리학 실습 중 급하게 제작한 프로그램입니다. 부족한 점이 많습니다 (마지막 수정 2026/03/30)
K4: 마음껏 사용해주시고 피드백, 원하는 기능, 수정해야할 점, 오류 등 알려주시면 감사하겠습니다. (alex0840@naver.com)
A6: 본 프로그램은 간호사들의 수면권 보장, 공평한 근무 배분, 그리고 병동의 안전한 운영을 위해 AI(구글 최적화 알고리즘)가 수백만 번의 계산을 거쳐 최적의 근무표를 짜주는 스마트 스케줄러입니다.
A8: 🚫 제 1장. 절대 불변의 기본 규칙 (자동 적용)
A10: 이 규칙들은 간호사의 건강과 병동 안전을 위해 컴퓨터가 절대적으로 지키도록 설계된 '수정 불가능한' 뼈대 규칙입니다.
A12: 1. 수면권 및 바이오리듬 보장 (최악의 듀티 차단)
A14: E ➔ D 금지: 이브닝 후 데이 출근 절대 금지
A16: M ➔ D, E ➔ M 금지: 미들(M) 근무 전후의 무리한 교대 금지
A18: N ➔ O ➔ D 금지: 나이트 후 하루 쉬고 데이 출근 절대 금지
A20: N ➔ O ➔ N 억제: 나이트 후 하루(또는 며칠) 쉬고 완충 듀티 없이 다시 나이트 출근 억제 (월초/월말 나이트 몰림 방지)
A22: O ➔ W ➔ O (퐁당퐁당) 금지: 오프 후 하루만 일하고 다시 오프를 부여하는 징검다리 근무 원천 차단
A24: 2. 환자 안전 및 병동 운영 보장
A26: 듀티별 필수 경력자(Charge) 배치: 모든 날짜의 D, E, N, M 근무에는 반드시 '차지 권한'이 있는 경력 간호사가 최소 1명 이상 배치됨. (신규들로만 구성된 듀티 발생 불가)
A28: 3. 나이트 전담(Night Keep) 특수 보호
... A170: 3. 간호사들 간의 총 근무 일수나 나이트 개수가 공평하게 딱 떨어지지 않았을 때

Sheet Setup
A1: Scheduler Controls
A2: Year | B2: 2026 | C2: Enter year | D2: Run: python nurse_scheduler_complete.py nurse_scheduler_complete.xlsx
A3: Month | B3: 3 | C3: 1-12 입력가능 | D3: Needs: pip install openpyxl ortools
A4: 이번 달 기본 오프 | B4: 11 | C4: 이 개수를 초과하면 근무표에 S로 표시됨
A6: Weekday D | B6: 3 | C6: 평일 day shift
A7: Weekday E | B7: 3 | C7: 평일 evening shift
A8: Weekday N | B8: 2 | C8: 평일 night shift
A9: Weekday M | B9: 0 | C9: 평일 middle shift
A11: Weekend/Holiday D | B11: 2 | C11: 주말 day shift
A12: Weekend/Holiday E | B12: 2 | C12: 주말 evening shift
A13: Weekend/Holiday N | B13: 2 | C13: 주말 night shift
A14: Weekend/Holiday M | B14: 0 | C14: 주말 middle shift
A16: Max consecutive work days | B16: 5 | C16: 듀티 최대 연속개수 ( 절대규칙 )
A17: Max consecutive D | B17: 4 | C17: 단일 day 최대 연속개수
A18: Max consecutive E | B18: 4 | C18: 단일 evening 최대 연속개수
... A29: Fairness weight: weekend work | B29: 2 | C29: Balances weekend/holiday work
A32: 설명
A33: Solver time limit (sec) (최대 계산 시간): 컴퓨터가 정답을 찾기 위해 고민할 수 있는 시간(초 단위)입니다. 조건이 많거나 에러(시간 초과)가 난다면 이 숫자를 600 정도로 넉넉하게 늘려주세요.
A35: Preference miss penalty (선호 근무 무시 벌점): 선생님들이 신청한 듀티(E or D 등)를 안 들어줬을 때 컴퓨터가 받는 벌점입니다. 이 숫자를 높게 바꿀수록 컴퓨터는 신청 듀티를 무조건 100% 들어주려고 노력하게 됩니다.
A37: Fairness weight (공평성 가중치): 간호사들끼리 특정 듀티의 개수가 차이 날 때마다 컴퓨터가 받는 벌점입니다. 이 숫자가 클수록 컴퓨터가 간호사들 간의 개수를 아주 칼같이 똑맞추려고 노력합니다. 10000점이 기본설정
A39: total work: 총 출근 일수를 똑같이 맞추려는 노력 점수
A41: nights: 나이트 개수를 똑같이 맞추려는 노력 점수
A43: days / evenings: 데이와 이브닝 개수를 똑같이 맞추려는 노력 점수
A45: weekend work: 주말 출근 횟수를 똑같이 맞추려는 노력 점수
A47: 절대규칙 : 만약 스케줄이 꼬여서 이 규칙을 어겨야만 근무표가 완성되는 상황이 오면, 컴퓨터는 규칙을 어기는 대신 차라리 "스케줄을 짤 수 없습니다!" 하고 에러를 내며 작동을 멈춥니다.

Sheet Nurses
A1: Nurse Name | B1: 경력(Y/N) | C1: 최대 오프(O+S) 개수 | D1: 나이트전담(Y/N) | E1: 프리셉터 | F1: 막내 여부(Y)
A2: 간호사1 | H2: 설명
A3: 간호사2 | H3: 신입 간호사 (연차 불가): 이번 달의 기본 오프 개수(예: 10개라면 10)를 적습니다. (기본 오프만 받고 S는 절대 생기지 않습니다.)
A4: 간호사3 | H4: 경력 간호사 (연차 사용): 기본 오프 + 남은 연차 개수(예: 10 + 2 = 12)를 적습니다.
A5: 간호사4 | H5: 제한 없음: 칸을 아예 비워두면 프로그램이 알아서 상황에 맞게 S를 분배합니다.
A6: 간호사5
A7: 간호사6 | H7: 경력간호사: Y 로 표시
A8: 간호사7 | H8: 신입간호사: N로(또는 빈칸) 표시
A9: 간호사8 | H9: y는 무조건 한명이상 체크해주세요. Y 라고 체크하면 각 듀티마다 y가 한명 이상 배정됩니다.
A10: 간호사9
A11: 간호사10 | H11: 나이트 전담 선생님의 D열 칸에만 Y (또는 소문자 y)를 적어줍니다. (나머지 선생님들은 비워두시면 됩니다.)
A12: 간호사11
A13: 간호사12 | H13: 프리셉터
A14: 간호사13 | H14: 신규 선생님 칸에 프리셉터 선생님의 이름을 적어주세요
A15: 간호사14 | H15: 홍길동 ➔ (1인분 가능) 프리셉터와 듀티를 똑같이 따라가면서, 병동 인원 1명으로 카운트됩니다.
A16: 간호사15 | H16: 홍길동 (no duty) ➔ (완전 신입) 프리셉터 듀티를 따라가지만, 투명인간 취급되어 병동 인원 카운트에서 제외됩니다. (※ 대소문자나 띄어쓰기는 상관없습니다. (NO DUTY), no duty 등 편하게 적으시면 됩니다!)
A17: 간호사16
A18: 간호사17 | H18: 막내 여부: 막내 여부를 두 명 이상 Y 체크하면 막내끼리는 같은 듀티에 가급적 배치하지 않습니다
A19: 간호사18
A20: 간호사19
A21: 간호사20
A22: 간호사21 | H22: 경력(Y/N) [차지 권한 부여]: 원하는 듀티에만 차지를 부여할 수 있습니다.
A23: 간호사22
A24: 간호사23 | H24: D차지 ➔ 데이 때만 경력직으로 인정
A25: 간호사24
A26: 간호사25 | H26: E차지 ➔ 이브닝 때만 경력직으로 인정
A27: 간호사26
A28: 간호사27 | H28: N차지 ➔ 나이트 때만 경력직으로 인정 (데이/이브 때는 일반 간호사 취급)
A29: 간호사28
A30: 간호사29 | H30: D, E 차지 또는 D/E차지 ➔ 데이와 이브닝 둘 다 경력직 인정
A31: 간호사30
A32: 간호사31 | H32: 데이, 이브닝 차지 ➔ 한글로 적어도 알파벳과 똑같이 알아듣습니다!
A33: 간호사32
A34: 간호사33 | H34: Y ➔ 모든 듀티에서 경력직으로 완전 인정
A35: 간호사34
A36: 간호사35 | H36: tip: 최대 오프 개수가 너무 적어서 모든 칸을 채울 수 없는 경우 에러가 납니다. 연차를 사용하거나 m 근무 추가, 하루 듀티 최대 수를 늘려주세요
A37: 간호사36
A38: 간호사37
A39: 간호사38
A40: 간호사39
...

Sheet Holidays
A1: Date (YYYY-MM-DD) | B1: Optional Note
E2: 설명
E3: 공휴일: 날짜만 적거나, 날짜를 적고 Note 칸에 '삼일절' 등 한글로 적습니다. (주말 듀티 인원으로 계산)
E5: 평일인데 유독 바빠서 '인원만 추가'하고 싶을 때 (한글 입력 금지!)
E7: 입력 예시: D2, E1, M, D1, E1
E8: 작동 원리: 한글 없이 알파벳과 숫자만 적으면, 평일 + 듀티추가로 인식합니다
E9: 예시: d2,n1 - 평일 기본 듀티 + 데이 2명, 나이트 1명을 더 추가합니다
E11: 공휴일이면서 동시에 '인원도 추가'하고 싶을 때
E12: 입력 예시: 삼일절 D2, 추석(E1), 대체휴일 D1, N1
E13: 작동 원리: 한글(기념일 이름)과 영어(듀티 추가)를 섞어서 적으면, 주말 듀티 인원 뼈대를 가져온 상태에서 추가 인원까지 완벽하게 덧붙여서 배정합니다.
E14: 예시: 한글날 ( d2, n1 ) - 평일 기본 듀티 + 데이 2명, 나이트 1명을 더 추가합니다
E17: 대소문자/띄어쓰기 자유: d2, D2, D 2, (D2) 모두 똑같이 인식합니다
E18: 숫자 생략 가능: 숫자를 안 적고 그냥 D 또는 M이라고만 적으면 자동으로 **'1명 추가'**로 똑똑하게 계산합니다.
E19: 여러 듀티 동시 추가: D2, E1, D2/E1, D2 E1 처럼 기호나 띄어쓰기로 대충 구분해서 적으셔도 다 알아듣습니다.

Sheet Restrictions
A1: Nurse | B1: NoNight (Y/N) | C1: Note
A2: =IF(Nurses!A2="","",Nurses!A2) -> 간호사1 | F2: 설명
A3: =IF(Nurses!A3="","",Nurses!A3) -> 간호사2 | F3: 이번 달에 나이트를 아예 하면 안 되는 선생님(임산부, 진단서 등)은 Y로 체크.
A4: =IF(Nurses!A4="","",Nurses!A4) -> 간호사3
A5: =IF(Nurses!A5="","",Nurses!A5) -> 간호사4
A6: =IF(Nurses!A6="","",Nurses!A6) -> 간호사5
A7: =IF(Nurses!A7="","",Nurses!A7) -> 간호사6
A8: =IF(Nurses!A8="","",Nurses!A8) -> 간호사7
A9: =IF(Nurses!A9="","",Nurses!A9) -> 간호사8
A10: =IF(Nurses!A10="","",Nurses!A10) -> 간호사9
A11: =IF(Nurses!A11="","",Nurses!A11) -> 간호사10
A12: =IF(Nurses!A12="","",Nurses!A12) -> 간호사11
A13: =IF(Nurses!A13="","",Nurses!A13) -> 간호사12
A14: =IF(Nurses!A14="","",Nurses!A14) -> 간호사13
A15: =IF(Nurses!A15="","",Nurses!A15) -> 간호사14
... A51: =IF(Nurses!A51="","",Nurses!A51) -> 간호사50

Sheet OffRequests
A1: Nurse | B1: 1 | C1: 2 | D1: 3 | E1: 4 | F1: 5 | G1: 6 | H1: 7 | I1: 8 | J1: 9 | K1: 10 | L1: 11 | M1: 12 | N1: 13 | O1: 14 | P1: 15 | Q1: 16 | R1: 17 | S1: 18 | T1: 19 | U1: 20 | V1: 21 | W1: 22 | X1: 23 | Y1: 24 | Z1: 25 | AA1: 26 | AB1: 27 | AC1: 28 | AD1: 29 | AE1: 30 | AF1: 31 | AH1: 설명
A2: =IF(Nurses!A2="","",Nurses!A2) -> 간호사1 | AH2: 1 (또는 O, OFF Y) 입력 : 1순위 오프 (절대 규칙 / Hard)
A3: =IF(Nurses!A3="","",Nurses!A3) -> 간호사2 | AH3: 100% 쉬게 해줍니다. (경조사, 필수 연차 등)
A4: =IF(Nurses!A4="","",Nurses!A4) -> 간호사3 | AH4: 만약 1순위에서 오프 배정이 안된다면 스케줄 안 만들어지고 에러가 생깁니다 ( 절대규칙 )
A5: =IF(Nurses!A5="","",Nurses!A5) -> 간호사4
A6: =IF(Nurses!A6="","",Nurses!A6) -> 간호사5 | AH6: 2 입력 : 2순위 오프 (강한 희망 / Soft)
A7: =IF(Nurses!A7="","",Nurses!A7) -> 간호사6 | AH7: 컴퓨터가 최대한 오프를 주려고 노력하지만, 도저히 스케줄이 안 나오면 눈물을 머금고 출근(D, E, N)으로 바꿉니다.
A8: =IF(Nurses!A8="","",Nurses!A8) -> 간호사7
A9: =IF(Nurses!A9="","",Nurses!A9) -> 간호사8 | AH9: 3 입력 : 3순위 오프 (약한 희망 / Soft)
A10: =IF(Nurses!A10="","",Nurses!A10) -> 간호사9 | AH10: 스케줄이 꼬일 때 가장 먼저 오프가 취소(반려)되는 타겟이 됩니다.
A11: =IF(Nurses!A11="","",Nurses!A11) -> 간호사10
A12: =IF(Nurses!A12="","",Nurses!A12) -> 간호사11 | AH12: ★ 스케줄 결과 확인
A13: =IF(Nurses!A13="","",Nurses!A13) -> 간호사12 | AH13: 컴퓨터가 도저히 안 되어서 2순위나 3순위 오프를 잘라내고 출근을 시켰다면,
A14: =IF(Nurses!A14="","",Nurses!A14) -> 간호사13 | AH14: 엑셀 결과표에 빨간색 칸으로 칠해지고 메모에 [3순위 오프 반려 (배정: D)] 처럼 표시되어 한눈에 취소된 사람을 찾아낼 수 있습니다!
A15: =IF(Nurses!A15="","",Nurses!A15) -> 간호사14
A16: =IF(Nurses!A16="","",Nurses!A16) -> 간호사15
A17: =IF(Nurses!A17="","",Nurses!A17) -> 간호사16
A18: =IF(Nurses!A18="","",Nurses!A18) -> 간호사17
A19: =IF(Nurses!A19="","",Nurses!A19) -> 간호사18
A20: =IF(Nurses!A20="","",Nurses!A20) -> 간호사19
A21: =IF(Nurses!A21="","",Nurses!A21) -> 간호사20
A22: =IF(Nurses!A22="","",Nurses!A22) -> 간호사21
A23: =IF(Nurses!A23="","",Nurses!A23) -> 간호사22
A24: =IF(Nurses!A24="","",Nurses!A24) -> 간호사23
A25: =IF(Nurses!A25="","",Nurses!A25) -> 간호사24
A26: =IF(Nurses!A26="","",Nurses!A26) -> 간호사25
... A51: =IF(Nurses!A51="","",Nurses!A51) -> 간호사50

Sheet ShiftPreferences
A1: Nurse | B1: 1 | C1: 2 | D1: 3 | E1: 4 | F1: 5 | G1: 6 | H1: 7 | I1: 8 | J1: 9 | K1: 10 | L1: 11 | M1: 12 | N1: 13 | O1: 14 | P1: 15 | Q1: 16 | R1: 17 | S1: 18 | T1: 19 | U1: 20 | V1: 21 | W1: 22 | X1: 23 | Y1: 24 | Z1: 25 | AA1: 26 | AB1: 27 | AC1: 28 | AD1: 29 | AE1: 30 | AF1: 31
A2: =IF(Nurses!A2="","",Nurses!A2) -> 간호사1
A3: =IF(Nurses!A3="","",Nurses!A3) -> 간호사2 | AH3: 설명
A4: =IF(Nurses!A4="","",Nurses!A4) -> 간호사3 | AH4: 선생님들이 원하는 근무를 신청하는 곳입니다.
A5: =IF(Nurses!A5="","",Nurses!A5) -> 간호사4
A6: =IF(Nurses!A6="","",Nurses!A6) -> 간호사5 | AH6: 다중 선택 기능: "데이나 이브닝 아무거나"가 가능합니다.
A7: =IF(Nurses!A7="","",Nurses!A7) -> 간호사6
A8: =IF(Nurses!A8="","",Nurses!A8) -> 간호사7 | AH8: 엑셀 칸에 E or D, E, D, E/D 라고 자유롭게 적으면, 컴퓨터가 알아서 둘 중 하나를 배정해 줍니다.
A9: =IF(Nurses!A9="","",Nurses!A9) -> 간호사8
A10: =IF(Nurses!A10="","",Nurses!A10) -> 간호사9 | AH10: Allowed markers: D, E, N, M 입력가능
A11: =IF(Nurses!A11="","",Nurses!A11) -> 간호사10
A12: =IF(Nurses!A12="","",Nurses!A12) -> 간호사11
A13: =IF(Nurses!A13="","",Nurses!A13) -> 간호사12
A14: =IF(Nurses!A14="","",Nurses!A14) -> 간호사13
A15: =IF(Nurses!A15="","",Nurses!A15) -> 간호사14
A16: =IF(Nurses!A16="","",Nurses!A16) -> 간호사15
A17: =IF(Nurses!A17="","",Nurses!A17) -> 간호사16
A18: =IF(Nurses!A18="","",Nurses!A18) -> 간호사17
A19: =IF(Nurses!A19="","",Nurses!A19) -> 간호사18
A20: =IF(Nurses!A20="","",Nurses!A20) -> 간호사19
A21: =IF(Nurses!A21="","",Nurses!A21) -> 간호사20
A22: =IF(Nurses!A22="","",Nurses!A22) -> 간호사21
... A51: =IF(Nurses!A51="","",Nurses!A51) -> 간호사50

Sheet PrevMonth
A1: Nurse Name | B1: D-5 | C1: D-4 | D1: D-3 | E1: D-2 | F1: D-1
A2: =IF(Nurses!A2="","",Nurses!A2) -> 간호사1 | J2: 설명
A3: =IF(Nurses!A3="","",Nurses!A3) -> 간호사2 | J3: 전 달 마지막 5일의 듀티를 작성합니다. 프로그램이 전 달 마지막 근무 5일을 규칙에 반영합니다
A4: =IF(Nurses!A4="","",Nurses!A4) -> 간호사3 | J4: D, E, N, M, O 중 하나를 적습니다. (칸을 비워두시면 무조건 오프(O)로 간주합니다.)
A5: =IF(Nurses!A5="","",Nurses!A5) -> 간호사4
A6: =IF(Nurses!A6="","",Nurses!A6) -> 간호사5
A7: =IF(Nurses!A7="","",Nurses!A7) -> 간호사6
A8: =IF(Nurses!A8="","",Nurses!A8) -> 간호사7
A9: =IF(Nurses!A9="","",Nurses!A9) -> 간호사8
A10: =IF(Nurses!A10="","",Nurses!A10) -> 간호사9
A11: =IF(Nurses!A11="","",Nurses!A11) -> 간호사10
A12: =IF(Nurses!A12="","",Nurses!A12) -> 간호사11
A13: =IF(Nurses!A13="","",Nurses!A13) -> 간호사12
A14: =IF(Nurses!A14="","",Nurses!A14) -> 간호사13
A15: =IF(Nurses!A15="","",Nurses!A15) -> 간호사14
A16: =IF(Nurses!A16="","",Nurses!A16) -> 간호사15
... A51: =IF(Nurses!A51="","",Nurses!A51) -> 간호사50

Sheet Schedule
A1: Final Schedule
A2: Type | B2: WH | C2: WD | D2: WD | E2: WD | F2: WD | G2: WD | H2: WH | I2: WH | J2: WD | K2: WD | L2: WD | M2: WD | N2: WD | O2: WH | P2: WH | Q2: WD | R2: WD | S2: WD | T2: WD | U2: WD | V2: WH | W2: WH | X2: WD | Y2: WD | Z2: WD | AA2: WD | AB2: WD | AC2: WH | AD2: WH | AE2: WD | AF2: WD
A3: Nurse | B3: 1 | C3: 2 | D3: 3 | E3: 4 | F3: 5 | G3: 6 | H3: 7 | I3: 8 | J3: 9 | K3: 10 | L3: 11 | M3: 12 | N3: 13 | O3: 14 | P3: 15 | Q3: 16 | R3: 17 | S3: 18 | T3: 19 | U3: 20 | V3: 21 | W3: 22 | X3: 23 | Y3: 24 | Z3: 25 | AA3: 26 | AB3: 27 | AC3: 28 | AD3: 29 | AE3: 30 | AF3: 31 | AG3: TotalWork | AH3: D | AI3: E | AJ3: N | AK3: Off(O+S) | AL3: S | AM3: WeekendWork | AN3: PrefReq | AO3: PrefHit | AP3: PrefMiss
A4: 간호사1
A5: 간호사2
A6: 간호사3
A7: 간호사4
A8: 간호사5
A9: 간호사6
A10: 간호사7
A11: 간호사8
A12: 간호사9
A13: 간호사10
A14: 간호사11
A15: 간호사12
... A30: 간호사27

Sheet RequestsSummary
A1: Nurse | B1: Date | C1: Type | D1: Requested | E1: Assigned | F1: Status

Sheet Validation
A1: Nurse | B1: MaxWorkRun | C1: MaxNightRun | D1: NightRestViol | E1: E→D Viol | F1: O-W-O Viol | G1: NoNight Viol | H1: OffReq Viol | I1: Overall

Sheet DailyCoverage
A1: Date | B1: Type | C1: ReqD | D1: ActD | E1: ReqE | F1: ActE | G1: ReqN | H1: ActN | I1: OK?
